2025-04-05 21:37:12    Task for /u/ianchen3/project/output/E0/MagusAln.fasta threw an exception:
[Errno 2] No such file or directory: '/u/ianchen3/project/data/ROSE/1000M1/R0/rose.aln.unalign.fasta'
2025-04-05 21:37:12    Traceback (most recent call last):
  File "/u/ianchen3/methods/MAGUS/magus/tasks/task.py", line 59, in run
    func(**self.taskArgs)
  File "/u/ianchen3/methods/MAGUS/magus/align/aligner.py", line 45, in runAlignmentTask
    decomposeSequences(context)
  File "/u/ianchen3/methods/MAGUS/magus/align/decompose/decomposer.py", line 44, in decomposeSequences
    buildDecomposition(context, subsetsDir)
  File "/u/ianchen3/methods/MAGUS/magus/align/decompose/decomposer.py", line 53, in buildDecomposition
    context.unalignedSequences = sequenceutils.readFromFasta(context.sequencesPath, removeDashes=True)
  File "/u/ianchen3/methods/MAGUS/magus/helpers/sequenceutils.py", line 19, in readFromFasta
    with open(filePath) as f:
FileNotFoundError: [Errno 2] No such file or directory: '/u/ianchen3/project/data/ROSE/1000M1/R0/rose.aln.unalign.fasta'

2025-04-05 21:37:12    MAGUS aborted with an exception..
2025-04-05 21:37:12    Task manager found a failed task: /u/ianchen3/project/output/E0/MagusAln.fasta
2025-04-05 21:37:12    Traceback (most recent call last):
  File "/u/ianchen3/methods/magus", line 37, in main
    mainAlignmentTask()
  File "/u/ianchen3/methods/MAGUS/magus/align/aligner.py", line 30, in mainAlignmentTask
    task.awaitTask()
  File "/u/ianchen3/methods/MAGUS/magus/tasks/task.py", line 47, in awaitTask
    awaitTasks([self])
  File "/u/ianchen3/methods/MAGUS/magus/tasks/task.py", line 94, in awaitTasks
    controller.awaitTasks(tasks)
  File "/u/ianchen3/methods/MAGUS/magus/tasks/controller.py", line 34, in awaitTasks
    observeTaskManager()
  File "/u/ianchen3/methods/MAGUS/magus/tasks/controller.py", line 53, in observeTaskManager
    runTask(task)
  File "/u/ianchen3/methods/MAGUS/magus/tasks/manager.py", line 220, in runTask
    task.run()
  File "/u/ianchen3/methods/MAGUS/magus/tasks/task.py", line 59, in run
    func(**self.taskArgs)
  File "/u/ianchen3/methods/MAGUS/magus/align/aligner.py", line 45, in runAlignmentTask
    decomposeSequences(context)
  File "/u/ianchen3/methods/MAGUS/magus/align/decompose/decomposer.py", line 44, in decomposeSequences
    buildDecomposition(context, subsetsDir)
  File "/u/ianchen3/methods/MAGUS/magus/align/decompose/decomposer.py", line 53, in buildDecomposition
    context.unalignedSequences = sequenceutils.readFromFasta(context.sequencesPath, removeDashes=True)
  File "/u/ianchen3/methods/MAGUS/magus/helpers/sequenceutils.py", line 19, in readFromFasta
    with open(filePath) as f:
FileNotFoundError: [Errno 2] No such file or directory: '/u/ianchen3/project/data/ROSE/1000M1/R0/rose.aln.unalign.fasta'

2025-04-05 21:55:28    Command encountered error: /u/ianchen3/methods/MAGUS/magus/tools/mafft/mafft --localpair --maxiterate 1000 --ep 0.123 --quiet --thread 64 --anysymbol /u/ianchen3/project/output/E0/magus_working_dir/graph/backbone_6_unalign.txt > /u/ianchen3/project/output/E0/magus_working_dir/graph/temp_backbone_6_mafft.txt
2025-04-05 21:55:28    Exit code: 1
2025-04-05 21:55:28    Output: /u/ianchen3/methods/MAGUS/magus/tools/mafft/mafftdir/bin/mafft: line 2719: 1594693 Killed                  "$prefix/tbfast" _ -u $unalignlevel $localparam -C $numthreads $seqtype $model -g $lexp -f $lgop -Q $spfactor -h $laof -L $usenaivepairscore $focusarg _ -+ $iterate -W $minimumweight -V "-"$gopdist -s $unalignlevel $legacygapopt $mergearg $termgapopt $outnum $addarg $add2ndhalfarg -C $numthreadstb $rnaopt $weightopt $treeinopt $treeoutopt $distoutopt $seqtype $model -f "-"$gop -Q $spfactor -h $aof $param_fft $localparam $algopt $treealg $scoreoutarg $focusarg < infile > /dev/null 2>> "$progressfile"

2025-04-05 21:55:28    Task for /u/ianchen3/project/output/E0/magus_working_dir/graph/backbone_6_mafft.txt threw an exception:
Command '/u/ianchen3/methods/MAGUS/magus/tools/mafft/mafft --localpair --maxiterate 1000 --ep 0.123 --quiet --thread 64 --anysymbol /u/ianchen3/project/output/E0/magus_working_dir/graph/backbone_6_unalign.txt > /u/ianchen3/project/output/E0/magus_working_dir/graph/temp_backbone_6_mafft.txt' returned non-zero exit status 1.
2025-04-05 21:55:28    Traceback (most recent call last):
  File "/u/ianchen3/methods/MAGUS/magus/tasks/task.py", line 59, in run
    func(**self.taskArgs)
  File "/u/ianchen3/methods/MAGUS/magus/tools/external_tools.py", line 19, in runCommand
    runner.check_returncode()
  File "/usr/lib64/python3.9/subprocess.py", line 460, in check_returncode
    raise CalledProcessError(self.returncode, self.args, self.stdout,
subprocess.CalledProcessError: Command '/u/ianchen3/methods/MAGUS/magus/tools/mafft/mafft --localpair --maxiterate 1000 --ep 0.123 --quiet --thread 64 --anysymbol /u/ianchen3/project/output/E0/magus_working_dir/graph/backbone_6_unalign.txt > /u/ianchen3/project/output/E0/magus_working_dir/graph/temp_backbone_6_mafft.txt' returned non-zero exit status 1.

2025-04-05 21:55:36    Task manager found a failed task: /u/ianchen3/project/output/E0/magus_working_dir/graph/backbone_6_mafft.txt
2025-04-05 21:55:36    Task manager is dead for some reason..
2025-04-05 21:55:36    Task for /u/ianchen3/project/output/E0/MagusAln.fasta threw an exception:
Command '/u/ianchen3/methods/MAGUS/magus/tools/mafft/mafft --localpair --maxiterate 1000 --ep 0.123 --quiet --thread 64 --anysymbol /u/ianchen3/project/output/E0/magus_working_dir/graph/backbone_6_unalign.txt > /u/ianchen3/project/output/E0/magus_working_dir/graph/temp_backbone_6_mafft.txt' returned non-zero exit status 1.
2025-04-05 21:55:36    Traceback (most recent call last):
  File "/u/ianchen3/methods/MAGUS/magus/tasks/task.py", line 59, in run
    func(**self.taskArgs)
  File "/u/ianchen3/methods/MAGUS/magus/align/aligner.py", line 52, in runAlignmentTask
    mergeSubalignments(context)
  File "/u/ianchen3/methods/MAGUS/magus/align/merge/merger.py", line 23, in mergeSubalignments
    buildGraph(context)
  File "/u/ianchen3/methods/MAGUS/magus/align/merge/graph_build/graph_builder.py", line 37, in buildGraph
    context.awaitSubalignments()
  File "/u/ianchen3/methods/MAGUS/magus/align/alignment_context.py", line 52, in awaitSubalignments
    task.awaitTasks(self.subalignmentTasks)
  File "/u/ianchen3/methods/MAGUS/magus/tasks/task.py", line 94, in awaitTasks
    controller.awaitTasks(tasks)
  File "/u/ianchen3/methods/MAGUS/magus/tasks/controller.py", line 34, in awaitTasks
    observeTaskManager()
  File "/u/ianchen3/methods/MAGUS/magus/tasks/controller.py", line 50, in observeTaskManager
    checkTaskManager()
  File "/u/ianchen3/methods/MAGUS/magus/tasks/controller.py", line 60, in checkTaskManager
    TaskManager.managerFuture.result()
  File "/usr/lib64/python3.9/concurrent/futures/_base.py", line 439, in result
    return self.__get_result()
  File "/usr/lib64/python3.9/concurrent/futures/_base.py", line 391, in __get_result
    raise self._exception
  File "/usr/lib64/python3.9/concurrent/futures/thread.py", line 58, in run
    result = self.fn(*self.args, **self.kwargs)
  File "/u/ianchen3/methods/MAGUS/magus/tasks/manager.py", line 83, in runTaskManager
    dealWithErrors()
  File "/u/ianchen3/methods/MAGUS/magus/tasks/manager.py", line 96, in dealWithErrors
    task.future.result()
  File "/usr/lib64/python3.9/concurrent/futures/_base.py", line 439, in result
    return self.__get_result()
  File "/usr/lib64/python3.9/concurrent/futures/_base.py", line 391, in __get_result
    raise self._exception
  File "/usr/lib64/python3.9/concurrent/futures/thread.py", line 58, in run
    result = self.fn(*self.args, **self.kwargs)
  File "/u/ianchen3/methods/MAGUS/magus/tasks/manager.py", line 220, in runTask
    task.run()
  File "/u/ianchen3/methods/MAGUS/magus/tasks/task.py", line 59, in run
    func(**self.taskArgs)
  File "/u/ianchen3/methods/MAGUS/magus/tools/external_tools.py", line 19, in runCommand
    runner.check_returncode()
  File "/usr/lib64/python3.9/subprocess.py", line 460, in check_returncode
    raise CalledProcessError(self.returncode, self.args, self.stdout,
subprocess.CalledProcessError: Command '/u/ianchen3/methods/MAGUS/magus/tools/mafft/mafft --localpair --maxiterate 1000 --ep 0.123 --quiet --thread 64 --anysymbol /u/ianchen3/project/output/E0/magus_working_dir/graph/backbone_6_unalign.txt > /u/ianchen3/project/output/E0/magus_working_dir/graph/temp_backbone_6_mafft.txt' returned non-zero exit status 1.

2025-04-05 21:55:36    MAGUS aborted with an exception..
2025-04-05 21:55:36    Traceback (most recent call last):
  File "/u/ianchen3/methods/magus", line 37, in main
    mainAlignmentTask()
  File "/u/ianchen3/methods/MAGUS/magus/align/aligner.py", line 30, in mainAlignmentTask
    task.awaitTask()
  File "/u/ianchen3/methods/MAGUS/magus/tasks/task.py", line 47, in awaitTask
    awaitTasks([self])
  File "/u/ianchen3/methods/MAGUS/magus/tasks/task.py", line 94, in awaitTasks
    controller.awaitTasks(tasks)
  File "/u/ianchen3/methods/MAGUS/magus/tasks/controller.py", line 34, in awaitTasks
    observeTaskManager()
  File "/u/ianchen3/methods/MAGUS/magus/tasks/controller.py", line 53, in observeTaskManager
    runTask(task)
  File "/u/ianchen3/methods/MAGUS/magus/tasks/manager.py", line 220, in runTask
    task.run()
  File "/u/ianchen3/methods/MAGUS/magus/tasks/task.py", line 59, in run
    func(**self.taskArgs)
  File "/u/ianchen3/methods/MAGUS/magus/align/aligner.py", line 52, in runAlignmentTask
    mergeSubalignments(context)
  File "/u/ianchen3/methods/MAGUS/magus/align/merge/merger.py", line 23, in mergeSubalignments
    buildGraph(context)
  File "/u/ianchen3/methods/MAGUS/magus/align/merge/graph_build/graph_builder.py", line 37, in buildGraph
    context.awaitSubalignments()
  File "/u/ianchen3/methods/MAGUS/magus/align/alignment_context.py", line 52, in awaitSubalignments
    task.awaitTasks(self.subalignmentTasks)
  File "/u/ianchen3/methods/MAGUS/magus/tasks/task.py", line 94, in awaitTasks
    controller.awaitTasks(tasks)
  File "/u/ianchen3/methods/MAGUS/magus/tasks/controller.py", line 34, in awaitTasks
    observeTaskManager()
  File "/u/ianchen3/methods/MAGUS/magus/tasks/controller.py", line 50, in observeTaskManager
    checkTaskManager()
  File "/u/ianchen3/methods/MAGUS/magus/tasks/controller.py", line 60, in checkTaskManager
    TaskManager.managerFuture.result()
  File "/usr/lib64/python3.9/concurrent/futures/_base.py", line 439, in result
    return self.__get_result()
  File "/usr/lib64/python3.9/concurrent/futures/_base.py", line 391, in __get_result
    raise self._exception
  File "/usr/lib64/python3.9/concurrent/futures/thread.py", line 58, in run
    result = self.fn(*self.args, **self.kwargs)
  File "/u/ianchen3/methods/MAGUS/magus/tasks/manager.py", line 83, in runTaskManager
    dealWithErrors()
  File "/u/ianchen3/methods/MAGUS/magus/tasks/manager.py", line 96, in dealWithErrors
    task.future.result()
  File "/usr/lib64/python3.9/concurrent/futures/_base.py", line 439, in result
    return self.__get_result()
  File "/usr/lib64/python3.9/concurrent/futures/_base.py", line 391, in __get_result
    raise self._exception
  File "/usr/lib64/python3.9/concurrent/futures/thread.py", line 58, in run
    result = self.fn(*self.args, **self.kwargs)
  File "/u/ianchen3/methods/MAGUS/magus/tasks/manager.py", line 220, in runTask
    task.run()
  File "/u/ianchen3/methods/MAGUS/magus/tasks/task.py", line 59, in run
    func(**self.taskArgs)
  File "/u/ianchen3/methods/MAGUS/magus/tools/external_tools.py", line 19, in runCommand
    runner.check_returncode()
  File "/usr/lib64/python3.9/subprocess.py", line 460, in check_returncode
    raise CalledProcessError(self.returncode, self.args, self.stdout,
subprocess.CalledProcessError: Command '/u/ianchen3/methods/MAGUS/magus/tools/mafft/mafft --localpair --maxiterate 1000 --ep 0.123 --quiet --thread 64 --anysymbol /u/ianchen3/project/output/E0/magus_working_dir/graph/backbone_6_unalign.txt > /u/ianchen3/project/output/E0/magus_working_dir/graph/temp_backbone_6_mafft.txt' returned non-zero exit status 1.

2025-04-05 21:55:36    Command encountered error: /u/ianchen3/methods/MAGUS/magus/tools/mafft/mafft --localpair --maxiterate 1000 --ep 0.123 --quiet --thread 64 --anysymbol /u/ianchen3/project/output/E0/magus_working_dir/graph/backbone_7_unalign.txt > /u/ianchen3/project/output/E0/magus_working_dir/graph/temp_backbone_7_mafft.txt
2025-04-05 21:55:36    Exit code: 1
2025-04-05 21:55:36    Output: /u/ianchen3/methods/MAGUS/magus/tools/mafft/mafftdir/bin/mafft: line 2719: 1598825 Killed                  "$prefix/tbfast" _ -u $unalignlevel $localparam -C $numthreads $seqtype $model -g $lexp -f $lgop -Q $spfactor -h $laof -L $usenaivepairscore $focusarg _ -+ $iterate -W $minimumweight -V "-"$gopdist -s $unalignlevel $legacygapopt $mergearg $termgapopt $outnum $addarg $add2ndhalfarg -C $numthreadstb $rnaopt $weightopt $treeinopt $treeoutopt $distoutopt $seqtype $model -f "-"$gop -Q $spfactor -h $aof $param_fft $localparam $algopt $treealg $scoreoutarg $focusarg < infile > /dev/null 2>> "$progressfile"

2025-04-05 21:55:36    Task for /u/ianchen3/project/output/E0/magus_working_dir/graph/backbone_7_mafft.txt threw an exception:
Command '/u/ianchen3/methods/MAGUS/magus/tools/mafft/mafft --localpair --maxiterate 1000 --ep 0.123 --quiet --thread 64 --anysymbol /u/ianchen3/project/output/E0/magus_working_dir/graph/backbone_7_unalign.txt > /u/ianchen3/project/output/E0/magus_working_dir/graph/temp_backbone_7_mafft.txt' returned non-zero exit status 1.
2025-04-05 21:55:36    Traceback (most recent call last):
  File "/u/ianchen3/methods/MAGUS/magus/tasks/task.py", line 59, in run
    func(**self.taskArgs)
  File "/u/ianchen3/methods/MAGUS/magus/tools/external_tools.py", line 19, in runCommand
    runner.check_returncode()
  File "/usr/lib64/python3.9/subprocess.py", line 460, in check_returncode
    raise CalledProcessError(self.returncode, self.args, self.stdout,
subprocess.CalledProcessError: Command '/u/ianchen3/methods/MAGUS/magus/tools/mafft/mafft --localpair --maxiterate 1000 --ep 0.123 --quiet --thread 64 --anysymbol /u/ianchen3/project/output/E0/magus_working_dir/graph/backbone_7_unalign.txt > /u/ianchen3/project/output/E0/magus_working_dir/graph/temp_backbone_7_mafft.txt' returned non-zero exit status 1.

2025-04-05 21:55:50    Command encountered error: /u/ianchen3/methods/MAGUS/magus/tools/mafft/mafft --localpair --maxiterate 1000 --ep 0.123 --quiet --thread 64 --anysymbol /u/ianchen3/project/output/E0/magus_working_dir/graph/backbone_4_unalign.txt > /u/ianchen3/project/output/E0/magus_working_dir/graph/temp_backbone_4_mafft.txt
2025-04-05 21:55:50    Exit code: 1
2025-04-05 21:55:50    Output: /u/ianchen3/methods/MAGUS/magus/tools/mafft/mafftdir/bin/mafft: line 2719: 1599595 Killed                  "$prefix/tbfast" _ -u $unalignlevel $localparam -C $numthreads $seqtype $model -g $lexp -f $lgop -Q $spfactor -h $laof -L $usenaivepairscore $focusarg _ -+ $iterate -W $minimumweight -V "-"$gopdist -s $unalignlevel $legacygapopt $mergearg $termgapopt $outnum $addarg $add2ndhalfarg -C $numthreadstb $rnaopt $weightopt $treeinopt $treeoutopt $distoutopt $seqtype $model -f "-"$gop -Q $spfactor -h $aof $param_fft $localparam $algopt $treealg $scoreoutarg $focusarg < infile > /dev/null 2>> "$progressfile"

2025-04-05 21:55:50    Task for /u/ianchen3/project/output/E0/magus_working_dir/graph/backbone_4_mafft.txt threw an exception:
Command '/u/ianchen3/methods/MAGUS/magus/tools/mafft/mafft --localpair --maxiterate 1000 --ep 0.123 --quiet --thread 64 --anysymbol /u/ianchen3/project/output/E0/magus_working_dir/graph/backbone_4_unalign.txt > /u/ianchen3/project/output/E0/magus_working_dir/graph/temp_backbone_4_mafft.txt' returned non-zero exit status 1.
2025-04-05 21:55:50    Traceback (most recent call last):
  File "/u/ianchen3/methods/MAGUS/magus/tasks/task.py", line 59, in run
    func(**self.taskArgs)
  File "/u/ianchen3/methods/MAGUS/magus/tools/external_tools.py", line 19, in runCommand
    runner.check_returncode()
  File "/usr/lib64/python3.9/subprocess.py", line 460, in check_returncode
    raise CalledProcessError(self.returncode, self.args, self.stdout,
subprocess.CalledProcessError: Command '/u/ianchen3/methods/MAGUS/magus/tools/mafft/mafft --localpair --maxiterate 1000 --ep 0.123 --quiet --thread 64 --anysymbol /u/ianchen3/project/output/E0/magus_working_dir/graph/backbone_4_unalign.txt > /u/ianchen3/project/output/E0/magus_working_dir/graph/temp_backbone_4_mafft.txt' returned non-zero exit status 1.

2025-04-05 21:56:30    Command encountered error: /u/ianchen3/methods/MAGUS/magus/tools/mafft/mafft --localpair --maxiterate 1000 --ep 0.123 --quiet --thread 64 --anysymbol /u/ianchen3/project/output/E0/magus_working_dir/decomposition/subset_9.txt > /u/ianchen3/project/output/E0/magus_working_dir/subalignments/temp_subalignment_subset_9.txt
2025-04-05 21:56:30    Exit code: 1
2025-04-05 21:56:30    Output: /u/ianchen3/methods/MAGUS/magus/tools/mafft/mafftdir/bin/mafft: line 2719: 1599467 Killed                  "$prefix/tbfast" _ -u $unalignlevel $localparam -C $numthreads $seqtype $model -g $lexp -f $lgop -Q $spfactor -h $laof -L $usenaivepairscore $focusarg _ -+ $iterate -W $minimumweight -V "-"$gopdist -s $unalignlevel $legacygapopt $mergearg $termgapopt $outnum $addarg $add2ndhalfarg -C $numthreadstb $rnaopt $weightopt $treeinopt $treeoutopt $distoutopt $seqtype $model -f "-"$gop -Q $spfactor -h $aof $param_fft $localparam $algopt $treealg $scoreoutarg $focusarg < infile > /dev/null 2>> "$progressfile"

2025-04-05 21:56:30    Task for /u/ianchen3/project/output/E0/magus_working_dir/subalignments/subalignment_subset_9.txt threw an exception:
Command '/u/ianchen3/methods/MAGUS/magus/tools/mafft/mafft --localpair --maxiterate 1000 --ep 0.123 --quiet --thread 64 --anysymbol /u/ianchen3/project/output/E0/magus_working_dir/decomposition/subset_9.txt > /u/ianchen3/project/output/E0/magus_working_dir/subalignments/temp_subalignment_subset_9.txt' returned non-zero exit status 1.
2025-04-05 21:56:30    Traceback (most recent call last):
  File "/u/ianchen3/methods/MAGUS/magus/tasks/task.py", line 59, in run
    func(**self.taskArgs)
  File "/u/ianchen3/methods/MAGUS/magus/tools/external_tools.py", line 19, in runCommand
    runner.check_returncode()
  File "/usr/lib64/python3.9/subprocess.py", line 460, in check_returncode
    raise CalledProcessError(self.returncode, self.args, self.stdout,
subprocess.CalledProcessError: Command '/u/ianchen3/methods/MAGUS/magus/tools/mafft/mafft --localpair --maxiterate 1000 --ep 0.123 --quiet --thread 64 --anysymbol /u/ianchen3/project/output/E0/magus_working_dir/decomposition/subset_9.txt > /u/ianchen3/project/output/E0/magus_working_dir/subalignments/temp_subalignment_subset_9.txt' returned non-zero exit status 1.

2025-04-05 21:56:31    Command encountered error: /u/ianchen3/methods/MAGUS/magus/tools/mafft/mafft --localpair --maxiterate 1000 --ep 0.123 --quiet --thread 64 --anysymbol /u/ianchen3/project/output/E0/magus_working_dir/decomposition/subset_6.txt > /u/ianchen3/project/output/E0/magus_working_dir/subalignments/temp_subalignment_subset_6.txt
2025-04-05 21:56:31    Exit code: 1
2025-04-05 21:56:31    Output: /u/ianchen3/methods/MAGUS/magus/tools/mafft/mafftdir/bin/mafft: line 2719: 1598953 Killed                  "$prefix/tbfast" _ -u $unalignlevel $localparam -C $numthreads $seqtype $model -g $lexp -f $lgop -Q $spfactor -h $laof -L $usenaivepairscore $focusarg _ -+ $iterate -W $minimumweight -V "-"$gopdist -s $unalignlevel $legacygapopt $mergearg $termgapopt $outnum $addarg $add2ndhalfarg -C $numthreadstb $rnaopt $weightopt $treeinopt $treeoutopt $distoutopt $seqtype $model -f "-"$gop -Q $spfactor -h $aof $param_fft $localparam $algopt $treealg $scoreoutarg $focusarg < infile > /dev/null 2>> "$progressfile"

2025-04-05 21:56:31    Task for /u/ianchen3/project/output/E0/magus_working_dir/subalignments/subalignment_subset_6.txt threw an exception:
Command '/u/ianchen3/methods/MAGUS/magus/tools/mafft/mafft --localpair --maxiterate 1000 --ep 0.123 --quiet --thread 64 --anysymbol /u/ianchen3/project/output/E0/magus_working_dir/decomposition/subset_6.txt > /u/ianchen3/project/output/E0/magus_working_dir/subalignments/temp_subalignment_subset_6.txt' returned non-zero exit status 1.
2025-04-05 21:56:31    Traceback (most recent call last):
  File "/u/ianchen3/methods/MAGUS/magus/tasks/task.py", line 59, in run
    func(**self.taskArgs)
  File "/u/ianchen3/methods/MAGUS/magus/tools/external_tools.py", line 19, in runCommand
    runner.check_returncode()
  File "/usr/lib64/python3.9/subprocess.py", line 460, in check_returncode
    raise CalledProcessError(self.returncode, self.args, self.stdout,
subprocess.CalledProcessError: Command '/u/ianchen3/methods/MAGUS/magus/tools/mafft/mafft --localpair --maxiterate 1000 --ep 0.123 --quiet --thread 64 --anysymbol /u/ianchen3/project/output/E0/magus_working_dir/decomposition/subset_6.txt > /u/ianchen3/project/output/E0/magus_working_dir/subalignments/temp_subalignment_subset_6.txt' returned non-zero exit status 1.

2025-04-05 21:56:59    Command encountered error: /u/ianchen3/methods/MAGUS/magus/tools/mafft/mafft --localpair --maxiterate 1000 --ep 0.123 --quiet --thread 64 --anysymbol /u/ianchen3/project/output/E0/magus_working_dir/graph/backbone_3_unalign.txt > /u/ianchen3/project/output/E0/magus_working_dir/graph/temp_backbone_3_mafft.txt
2025-04-05 21:56:59    Exit code: 1
2025-04-05 21:56:59    Output: /u/ianchen3/methods/MAGUS/magus/tools/mafft/mafftdir/bin/mafft: line 2719: 1599755 Killed                  "$prefix/tbfast" _ -u $unalignlevel $localparam -C $numthreads $seqtype $model -g $lexp -f $lgop -Q $spfactor -h $laof -L $usenaivepairscore $focusarg _ -+ $iterate -W $minimumweight -V "-"$gopdist -s $unalignlevel $legacygapopt $mergearg $termgapopt $outnum $addarg $add2ndhalfarg -C $numthreadstb $rnaopt $weightopt $treeinopt $treeoutopt $distoutopt $seqtype $model -f "-"$gop -Q $spfactor -h $aof $param_fft $localparam $algopt $treealg $scoreoutarg $focusarg < infile > /dev/null 2>> "$progressfile"

2025-04-05 21:56:59    Task for /u/ianchen3/project/output/E0/magus_working_dir/graph/backbone_3_mafft.txt threw an exception:
Command '/u/ianchen3/methods/MAGUS/magus/tools/mafft/mafft --localpair --maxiterate 1000 --ep 0.123 --quiet --thread 64 --anysymbol /u/ianchen3/project/output/E0/magus_working_dir/graph/backbone_3_unalign.txt > /u/ianchen3/project/output/E0/magus_working_dir/graph/temp_backbone_3_mafft.txt' returned non-zero exit status 1.
2025-04-05 21:56:59    Traceback (most recent call last):
  File "/u/ianchen3/methods/MAGUS/magus/tasks/task.py", line 59, in run
    func(**self.taskArgs)
  File "/u/ianchen3/methods/MAGUS/magus/tools/external_tools.py", line 19, in runCommand
    runner.check_returncode()
  File "/usr/lib64/python3.9/subprocess.py", line 460, in check_returncode
    raise CalledProcessError(self.returncode, self.args, self.stdout,
subprocess.CalledProcessError: Command '/u/ianchen3/methods/MAGUS/magus/tools/mafft/mafft --localpair --maxiterate 1000 --ep 0.123 --quiet --thread 64 --anysymbol /u/ianchen3/project/output/E0/magus_working_dir/graph/backbone_3_unalign.txt > /u/ianchen3/project/output/E0/magus_working_dir/graph/temp_backbone_3_mafft.txt' returned non-zero exit status 1.

2025-04-05 21:57:00    Command encountered error: /u/ianchen3/methods/MAGUS/magus/tools/mafft/mafft --localpair --maxiterate 1000 --ep 0.123 --quiet --thread 64 --anysymbol /u/ianchen3/project/output/E0/magus_working_dir/graph/backbone_10_unalign.txt > /u/ianchen3/project/output/E0/magus_working_dir/graph/temp_backbone_10_mafft.txt
2025-04-05 21:57:00    Exit code: 1
2025-04-05 21:57:00    Output: /u/ianchen3/methods/MAGUS/magus/tools/mafft/mafftdir/bin/mafft: line 2719: 1603343 Killed                  "$prefix/tbfast" _ -u $unalignlevel $localparam -C $numthreads $seqtype $model -g $lexp -f $lgop -Q $spfactor -h $laof -L $usenaivepairscore $focusarg _ -+ $iterate -W $minimumweight -V "-"$gopdist -s $unalignlevel $legacygapopt $mergearg $termgapopt $outnum $addarg $add2ndhalfarg -C $numthreadstb $rnaopt $weightopt $treeinopt $treeoutopt $distoutopt $seqtype $model -f "-"$gop -Q $spfactor -h $aof $param_fft $localparam $algopt $treealg $scoreoutarg $focusarg < infile > /dev/null 2>> "$progressfile"

2025-04-05 21:57:00    Task for /u/ianchen3/project/output/E0/magus_working_dir/graph/backbone_10_mafft.txt threw an exception:
Command '/u/ianchen3/methods/MAGUS/magus/tools/mafft/mafft --localpair --maxiterate 1000 --ep 0.123 --quiet --thread 64 --anysymbol /u/ianchen3/project/output/E0/magus_working_dir/graph/backbone_10_unalign.txt > /u/ianchen3/project/output/E0/magus_working_dir/graph/temp_backbone_10_mafft.txt' returned non-zero exit status 1.
2025-04-05 21:57:00    Traceback (most recent call last):
  File "/u/ianchen3/methods/MAGUS/magus/tasks/task.py", line 59, in run
    func(**self.taskArgs)
  File "/u/ianchen3/methods/MAGUS/magus/tools/external_tools.py", line 19, in runCommand
    runner.check_returncode()
  File "/usr/lib64/python3.9/subprocess.py", line 460, in check_returncode
    raise CalledProcessError(self.returncode, self.args, self.stdout,
subprocess.CalledProcessError: Command '/u/ianchen3/methods/MAGUS/magus/tools/mafft/mafft --localpair --maxiterate 1000 --ep 0.123 --quiet --thread 64 --anysymbol /u/ianchen3/project/output/E0/magus_working_dir/graph/backbone_10_unalign.txt > /u/ianchen3/project/output/E0/magus_working_dir/graph/temp_backbone_10_mafft.txt' returned non-zero exit status 1.

2025-04-05 22:20:08    Command encountered error: /u/ianchen3/methods/MAGUS/magus/tools/mafft/mafft --localpair --maxiterate 1000 --ep 0.123 --quiet --thread 64 --anysymbol /u/ianchen3/project/output/E0/magus_working_dir/graph/backbone_3_unalign.txt > /u/ianchen3/project/output/E0/magus_working_dir/graph/temp_backbone_3_mafft.txt
2025-04-05 22:20:08    Exit code: 1
2025-04-05 22:20:08    Output: /u/ianchen3/methods/MAGUS/magus/tools/mafft/mafftdir/bin/mafft: line 2719: 1681124 Killed                  "$prefix/tbfast" _ -u $unalignlevel $localparam -C $numthreads $seqtype $model -g $lexp -f $lgop -Q $spfactor -h $laof -L $usenaivepairscore $focusarg _ -+ $iterate -W $minimumweight -V "-"$gopdist -s $unalignlevel $legacygapopt $mergearg $termgapopt $outnum $addarg $add2ndhalfarg -C $numthreadstb $rnaopt $weightopt $treeinopt $treeoutopt $distoutopt $seqtype $model -f "-"$gop -Q $spfactor -h $aof $param_fft $localparam $algopt $treealg $scoreoutarg $focusarg < infile > /dev/null 2>> "$progressfile"

2025-04-05 22:20:08    Task for /u/ianchen3/project/output/E0/magus_working_dir/graph/backbone_3_mafft.txt threw an exception:
Command '/u/ianchen3/methods/MAGUS/magus/tools/mafft/mafft --localpair --maxiterate 1000 --ep 0.123 --quiet --thread 64 --anysymbol /u/ianchen3/project/output/E0/magus_working_dir/graph/backbone_3_unalign.txt > /u/ianchen3/project/output/E0/magus_working_dir/graph/temp_backbone_3_mafft.txt' returned non-zero exit status 1.
2025-04-05 22:20:08    Traceback (most recent call last):
  File "/u/ianchen3/methods/MAGUS/magus/tasks/task.py", line 59, in run
    func(**self.taskArgs)
  File "/u/ianchen3/methods/MAGUS/magus/tools/external_tools.py", line 19, in runCommand
    runner.check_returncode()
  File "/usr/lib64/python3.9/subprocess.py", line 460, in check_returncode
    raise CalledProcessError(self.returncode, self.args, self.stdout,
subprocess.CalledProcessError: Command '/u/ianchen3/methods/MAGUS/magus/tools/mafft/mafft --localpair --maxiterate 1000 --ep 0.123 --quiet --thread 64 --anysymbol /u/ianchen3/project/output/E0/magus_working_dir/graph/backbone_3_unalign.txt > /u/ianchen3/project/output/E0/magus_working_dir/graph/temp_backbone_3_mafft.txt' returned non-zero exit status 1.

2025-04-05 22:20:08    Task manager found a failed task: /u/ianchen3/project/output/E0/magus_working_dir/graph/backbone_3_mafft.txt
2025-04-05 22:20:08    Task manager is dead for some reason..
2025-04-05 22:20:08    Task for /u/ianchen3/project/output/E0/MagusAln.fasta threw an exception:
Command '/u/ianchen3/methods/MAGUS/magus/tools/mafft/mafft --localpair --maxiterate 1000 --ep 0.123 --quiet --thread 64 --anysymbol /u/ianchen3/project/output/E0/magus_working_dir/graph/backbone_3_unalign.txt > /u/ianchen3/project/output/E0/magus_working_dir/graph/temp_backbone_3_mafft.txt' returned non-zero exit status 1.
2025-04-05 22:20:08    Traceback (most recent call last):
  File "/u/ianchen3/methods/MAGUS/magus/tasks/task.py", line 59, in run
    func(**self.taskArgs)
  File "/u/ianchen3/methods/MAGUS/magus/align/aligner.py", line 52, in runAlignmentTask
    mergeSubalignments(context)
  File "/u/ianchen3/methods/MAGUS/magus/align/merge/merger.py", line 23, in mergeSubalignments
    buildGraph(context)
  File "/u/ianchen3/methods/MAGUS/magus/align/merge/graph_build/graph_builder.py", line 37, in buildGraph
    context.awaitSubalignments()
  File "/u/ianchen3/methods/MAGUS/magus/align/alignment_context.py", line 52, in awaitSubalignments
    task.awaitTasks(self.subalignmentTasks)
  File "/u/ianchen3/methods/MAGUS/magus/tasks/task.py", line 94, in awaitTasks
    controller.awaitTasks(tasks)
  File "/u/ianchen3/methods/MAGUS/magus/tasks/controller.py", line 34, in awaitTasks
    observeTaskManager()
  File "/u/ianchen3/methods/MAGUS/magus/tasks/controller.py", line 50, in observeTaskManager
    checkTaskManager()
  File "/u/ianchen3/methods/MAGUS/magus/tasks/controller.py", line 60, in checkTaskManager
    TaskManager.managerFuture.result()
  File "/usr/lib64/python3.9/concurrent/futures/_base.py", line 439, in result
    return self.__get_result()
  File "/usr/lib64/python3.9/concurrent/futures/_base.py", line 391, in __get_result
    raise self._exception
  File "/usr/lib64/python3.9/concurrent/futures/thread.py", line 58, in run
    result = self.fn(*self.args, **self.kwargs)
  File "/u/ianchen3/methods/MAGUS/magus/tasks/manager.py", line 83, in runTaskManager
    dealWithErrors()
  File "/u/ianchen3/methods/MAGUS/magus/tasks/manager.py", line 96, in dealWithErrors
    task.future.result()
  File "/usr/lib64/python3.9/concurrent/futures/_base.py", line 439, in result
    return self.__get_result()
  File "/usr/lib64/python3.9/concurrent/futures/_base.py", line 391, in __get_result
    raise self._exception
  File "/usr/lib64/python3.9/concurrent/futures/thread.py", line 58, in run
    result = self.fn(*self.args, **self.kwargs)
  File "/u/ianchen3/methods/MAGUS/magus/tasks/manager.py", line 220, in runTask
    task.run()
  File "/u/ianchen3/methods/MAGUS/magus/tasks/task.py", line 59, in run
    func(**self.taskArgs)
  File "/u/ianchen3/methods/MAGUS/magus/tools/external_tools.py", line 19, in runCommand
    runner.check_returncode()
  File "/usr/lib64/python3.9/subprocess.py", line 460, in check_returncode
    raise CalledProcessError(self.returncode, self.args, self.stdout,
subprocess.CalledProcessError: Command '/u/ianchen3/methods/MAGUS/magus/tools/mafft/mafft --localpair --maxiterate 1000 --ep 0.123 --quiet --thread 64 --anysymbol /u/ianchen3/project/output/E0/magus_working_dir/graph/backbone_3_unalign.txt > /u/ianchen3/project/output/E0/magus_working_dir/graph/temp_backbone_3_mafft.txt' returned non-zero exit status 1.

2025-04-05 22:20:08    MAGUS aborted with an exception..
2025-04-05 22:20:08    Traceback (most recent call last):
  File "/u/ianchen3/methods/magus", line 37, in main
    mainAlignmentTask()
  File "/u/ianchen3/methods/MAGUS/magus/align/aligner.py", line 30, in mainAlignmentTask
    task.awaitTask()
  File "/u/ianchen3/methods/MAGUS/magus/tasks/task.py", line 47, in awaitTask
    awaitTasks([self])
  File "/u/ianchen3/methods/MAGUS/magus/tasks/task.py", line 94, in awaitTasks
    controller.awaitTasks(tasks)
  File "/u/ianchen3/methods/MAGUS/magus/tasks/controller.py", line 34, in awaitTasks
    observeTaskManager()
  File "/u/ianchen3/methods/MAGUS/magus/tasks/controller.py", line 53, in observeTaskManager
    runTask(task)
  File "/u/ianchen3/methods/MAGUS/magus/tasks/manager.py", line 220, in runTask
    task.run()
  File "/u/ianchen3/methods/MAGUS/magus/tasks/task.py", line 59, in run
    func(**self.taskArgs)
  File "/u/ianchen3/methods/MAGUS/magus/align/aligner.py", line 52, in runAlignmentTask
    mergeSubalignments(context)
  File "/u/ianchen3/methods/MAGUS/magus/align/merge/merger.py", line 23, in mergeSubalignments
    buildGraph(context)
  File "/u/ianchen3/methods/MAGUS/magus/align/merge/graph_build/graph_builder.py", line 37, in buildGraph
    context.awaitSubalignments()
  File "/u/ianchen3/methods/MAGUS/magus/align/alignment_context.py", line 52, in awaitSubalignments
    task.awaitTasks(self.subalignmentTasks)
  File "/u/ianchen3/methods/MAGUS/magus/tasks/task.py", line 94, in awaitTasks
    controller.awaitTasks(tasks)
  File "/u/ianchen3/methods/MAGUS/magus/tasks/controller.py", line 34, in awaitTasks
    observeTaskManager()
  File "/u/ianchen3/methods/MAGUS/magus/tasks/controller.py", line 50, in observeTaskManager
    checkTaskManager()
  File "/u/ianchen3/methods/MAGUS/magus/tasks/controller.py", line 60, in checkTaskManager
    TaskManager.managerFuture.result()
  File "/usr/lib64/python3.9/concurrent/futures/_base.py", line 439, in result
    return self.__get_result()
  File "/usr/lib64/python3.9/concurrent/futures/_base.py", line 391, in __get_result
    raise self._exception
  File "/usr/lib64/python3.9/concurrent/futures/thread.py", line 58, in run
    result = self.fn(*self.args, **self.kwargs)
  File "/u/ianchen3/methods/MAGUS/magus/tasks/manager.py", line 83, in runTaskManager
    dealWithErrors()
  File "/u/ianchen3/methods/MAGUS/magus/tasks/manager.py", line 96, in dealWithErrors
    task.future.result()
  File "/usr/lib64/python3.9/concurrent/futures/_base.py", line 439, in result
    return self.__get_result()
  File "/usr/lib64/python3.9/concurrent/futures/_base.py", line 391, in __get_result
    raise self._exception
  File "/usr/lib64/python3.9/concurrent/futures/thread.py", line 58, in run
    result = self.fn(*self.args, **self.kwargs)
  File "/u/ianchen3/methods/MAGUS/magus/tasks/manager.py", line 220, in runTask
    task.run()
  File "/u/ianchen3/methods/MAGUS/magus/tasks/task.py", line 59, in run
    func(**self.taskArgs)
  File "/u/ianchen3/methods/MAGUS/magus/tools/external_tools.py", line 19, in runCommand
    runner.check_returncode()
  File "/usr/lib64/python3.9/subprocess.py", line 460, in check_returncode
    raise CalledProcessError(self.returncode, self.args, self.stdout,
subprocess.CalledProcessError: Command '/u/ianchen3/methods/MAGUS/magus/tools/mafft/mafft --localpair --maxiterate 1000 --ep 0.123 --quiet --thread 64 --anysymbol /u/ianchen3/project/output/E0/magus_working_dir/graph/backbone_3_unalign.txt > /u/ianchen3/project/output/E0/magus_working_dir/graph/temp_backbone_3_mafft.txt' returned non-zero exit status 1.

2025-04-05 22:20:22    Command encountered error: /u/ianchen3/methods/MAGUS/magus/tools/mafft/mafft --localpair --maxiterate 1000 --ep 0.123 --quiet --thread 64 --anysymbol /u/ianchen3/project/output/E0/magus_working_dir/graph/backbone_5_unalign.txt > /u/ianchen3/project/output/E0/magus_working_dir/graph/temp_backbone_5_mafft.txt
2025-04-05 22:20:22    Exit code: 1
2025-04-05 22:20:22    Output: /u/ianchen3/methods/MAGUS/magus/tools/mafft/mafftdir/bin/mafft: line 2719: 1681727 Killed                  "$prefix/tbfast" _ -u $unalignlevel $localparam -C $numthreads $seqtype $model -g $lexp -f $lgop -Q $spfactor -h $laof -L $usenaivepairscore $focusarg _ -+ $iterate -W $minimumweight -V "-"$gopdist -s $unalignlevel $legacygapopt $mergearg $termgapopt $outnum $addarg $add2ndhalfarg -C $numthreadstb $rnaopt $weightopt $treeinopt $treeoutopt $distoutopt $seqtype $model -f "-"$gop -Q $spfactor -h $aof $param_fft $localparam $algopt $treealg $scoreoutarg $focusarg < infile > /dev/null 2>> "$progressfile"

2025-04-05 22:20:22    Task for /u/ianchen3/project/output/E0/magus_working_dir/graph/backbone_5_mafft.txt threw an exception:
Command '/u/ianchen3/methods/MAGUS/magus/tools/mafft/mafft --localpair --maxiterate 1000 --ep 0.123 --quiet --thread 64 --anysymbol /u/ianchen3/project/output/E0/magus_working_dir/graph/backbone_5_unalign.txt > /u/ianchen3/project/output/E0/magus_working_dir/graph/temp_backbone_5_mafft.txt' returned non-zero exit status 1.
2025-04-05 22:20:22    Traceback (most recent call last):
  File "/u/ianchen3/methods/MAGUS/magus/tasks/task.py", line 59, in run
    func(**self.taskArgs)
  File "/u/ianchen3/methods/MAGUS/magus/tools/external_tools.py", line 19, in runCommand
    runner.check_returncode()
  File "/usr/lib64/python3.9/subprocess.py", line 460, in check_returncode
    raise CalledProcessError(self.returncode, self.args, self.stdout,
subprocess.CalledProcessError: Command '/u/ianchen3/methods/MAGUS/magus/tools/mafft/mafft --localpair --maxiterate 1000 --ep 0.123 --quiet --thread 64 --anysymbol /u/ianchen3/project/output/E0/magus_working_dir/graph/backbone_5_unalign.txt > /u/ianchen3/project/output/E0/magus_working_dir/graph/temp_backbone_5_mafft.txt' returned non-zero exit status 1.

2025-04-05 22:20:41    Command encountered error: /u/ianchen3/methods/MAGUS/magus/tools/mafft/mafft --localpair --maxiterate 1000 --ep 0.123 --quiet --thread 64 --anysymbol /u/ianchen3/project/output/E0/magus_working_dir/graph/backbone_8_unalign.txt > /u/ianchen3/project/output/E0/magus_working_dir/graph/temp_backbone_8_mafft.txt
2025-04-05 22:20:41    Exit code: 1
2025-04-05 22:20:41    Output: /u/ianchen3/methods/MAGUS/magus/tools/mafft/mafftdir/bin/mafft: line 2719: 1680769 Killed                  "$prefix/tbfast" _ -u $unalignlevel $localparam -C $numthreads $seqtype $model -g $lexp -f $lgop -Q $spfactor -h $laof -L $usenaivepairscore $focusarg _ -+ $iterate -W $minimumweight -V "-"$gopdist -s $unalignlevel $legacygapopt $mergearg $termgapopt $outnum $addarg $add2ndhalfarg -C $numthreadstb $rnaopt $weightopt $treeinopt $treeoutopt $distoutopt $seqtype $model -f "-"$gop -Q $spfactor -h $aof $param_fft $localparam $algopt $treealg $scoreoutarg $focusarg < infile > /dev/null 2>> "$progressfile"

2025-04-05 22:20:41    Task for /u/ianchen3/project/output/E0/magus_working_dir/graph/backbone_8_mafft.txt threw an exception:
Command '/u/ianchen3/methods/MAGUS/magus/tools/mafft/mafft --localpair --maxiterate 1000 --ep 0.123 --quiet --thread 64 --anysymbol /u/ianchen3/project/output/E0/magus_working_dir/graph/backbone_8_unalign.txt > /u/ianchen3/project/output/E0/magus_working_dir/graph/temp_backbone_8_mafft.txt' returned non-zero exit status 1.
2025-04-05 22:20:41    Traceback (most recent call last):
  File "/u/ianchen3/methods/MAGUS/magus/tasks/task.py", line 59, in run
    func(**self.taskArgs)
  File "/u/ianchen3/methods/MAGUS/magus/tools/external_tools.py", line 19, in runCommand
    runner.check_returncode()
  File "/usr/lib64/python3.9/subprocess.py", line 460, in check_returncode
    raise CalledProcessError(self.returncode, self.args, self.stdout,
subprocess.CalledProcessError: Command '/u/ianchen3/methods/MAGUS/magus/tools/mafft/mafft --localpair --maxiterate 1000 --ep 0.123 --quiet --thread 64 --anysymbol /u/ianchen3/project/output/E0/magus_working_dir/graph/backbone_8_unalign.txt > /u/ianchen3/project/output/E0/magus_working_dir/graph/temp_backbone_8_mafft.txt' returned non-zero exit status 1.

2025-04-05 22:21:00    Command encountered error: /u/ianchen3/methods/MAGUS/magus/tools/mafft/mafft --localpair --maxiterate 1000 --ep 0.123 --quiet --thread 64 --anysymbol /u/ianchen3/project/output/E0/magus_working_dir/graph/backbone_2_unalign.txt > /u/ianchen3/project/output/E0/magus_working_dir/graph/temp_backbone_2_mafft.txt
2025-04-05 22:21:00    Exit code: 1
2025-04-05 22:21:00    Output: /u/ianchen3/methods/MAGUS/magus/tools/mafft/mafftdir/bin/mafft: line 2719: 1685649 Killed                  "$prefix/tbfast" _ -u $unalignlevel $localparam -C $numthreads $seqtype $model -g $lexp -f $lgop -Q $spfactor -h $laof -L $usenaivepairscore $focusarg _ -+ $iterate -W $minimumweight -V "-"$gopdist -s $unalignlevel $legacygapopt $mergearg $termgapopt $outnum $addarg $add2ndhalfarg -C $numthreadstb $rnaopt $weightopt $treeinopt $treeoutopt $distoutopt $seqtype $model -f "-"$gop -Q $spfactor -h $aof $param_fft $localparam $algopt $treealg $scoreoutarg $focusarg < infile > /dev/null 2>> "$progressfile"

2025-04-05 22:21:00    Task for /u/ianchen3/project/output/E0/magus_working_dir/graph/backbone_2_mafft.txt threw an exception:
Command '/u/ianchen3/methods/MAGUS/magus/tools/mafft/mafft --localpair --maxiterate 1000 --ep 0.123 --quiet --thread 64 --anysymbol /u/ianchen3/project/output/E0/magus_working_dir/graph/backbone_2_unalign.txt > /u/ianchen3/project/output/E0/magus_working_dir/graph/temp_backbone_2_mafft.txt' returned non-zero exit status 1.
2025-04-05 22:21:00    Traceback (most recent call last):
  File "/u/ianchen3/methods/MAGUS/magus/tasks/task.py", line 59, in run
    func(**self.taskArgs)
  File "/u/ianchen3/methods/MAGUS/magus/tools/external_tools.py", line 19, in runCommand
    runner.check_returncode()
  File "/usr/lib64/python3.9/subprocess.py", line 460, in check_returncode
    raise CalledProcessError(self.returncode, self.args, self.stdout,
subprocess.CalledProcessError: Command '/u/ianchen3/methods/MAGUS/magus/tools/mafft/mafft --localpair --maxiterate 1000 --ep 0.123 --quiet --thread 64 --anysymbol /u/ianchen3/project/output/E0/magus_working_dir/graph/backbone_2_unalign.txt > /u/ianchen3/project/output/E0/magus_working_dir/graph/temp_backbone_2_mafft.txt' returned non-zero exit status 1.

2025-04-05 22:21:22    Command encountered error: /u/ianchen3/methods/MAGUS/magus/tools/mafft/mafft --localpair --maxiterate 1000 --ep 0.123 --quiet --thread 64 --anysymbol /u/ianchen3/project/output/E0/magus_working_dir/graph/backbone_9_unalign.txt > /u/ianchen3/project/output/E0/magus_working_dir/graph/temp_backbone_9_mafft.txt
2025-04-05 22:21:22    Exit code: 1
2025-04-05 22:21:22    Output: /u/ianchen3/methods/MAGUS/magus/tools/mafft/mafftdir/bin/mafft: line 2719: 1685867 Killed                  "$prefix/tbfast" _ -u $unalignlevel $localparam -C $numthreads $seqtype $model -g $lexp -f $lgop -Q $spfactor -h $laof -L $usenaivepairscore $focusarg _ -+ $iterate -W $minimumweight -V "-"$gopdist -s $unalignlevel $legacygapopt $mergearg $termgapopt $outnum $addarg $add2ndhalfarg -C $numthreadstb $rnaopt $weightopt $treeinopt $treeoutopt $distoutopt $seqtype $model -f "-"$gop -Q $spfactor -h $aof $param_fft $localparam $algopt $treealg $scoreoutarg $focusarg < infile > /dev/null 2>> "$progressfile"

2025-04-05 22:21:22    Task for /u/ianchen3/project/output/E0/magus_working_dir/graph/backbone_9_mafft.txt threw an exception:
Command '/u/ianchen3/methods/MAGUS/magus/tools/mafft/mafft --localpair --maxiterate 1000 --ep 0.123 --quiet --thread 64 --anysymbol /u/ianchen3/project/output/E0/magus_working_dir/graph/backbone_9_unalign.txt > /u/ianchen3/project/output/E0/magus_working_dir/graph/temp_backbone_9_mafft.txt' returned non-zero exit status 1.
2025-04-05 22:21:22    Traceback (most recent call last):
  File "/u/ianchen3/methods/MAGUS/magus/tasks/task.py", line 59, in run
    func(**self.taskArgs)
  File "/u/ianchen3/methods/MAGUS/magus/tools/external_tools.py", line 19, in runCommand
    runner.check_returncode()
  File "/usr/lib64/python3.9/subprocess.py", line 460, in check_returncode
    raise CalledProcessError(self.returncode, self.args, self.stdout,
subprocess.CalledProcessError: Command '/u/ianchen3/methods/MAGUS/magus/tools/mafft/mafft --localpair --maxiterate 1000 --ep 0.123 --quiet --thread 64 --anysymbol /u/ianchen3/project/output/E0/magus_working_dir/graph/backbone_9_unalign.txt > /u/ianchen3/project/output/E0/magus_working_dir/graph/temp_backbone_9_mafft.txt' returned non-zero exit status 1.

2025-04-05 22:21:31    Command encountered error: /u/ianchen3/methods/MAGUS/magus/tools/mafft/mafft --localpair --maxiterate 1000 --ep 0.123 --quiet --thread 64 --anysymbol /u/ianchen3/project/output/E0/magus_working_dir/graph/backbone_8_unalign.txt > /u/ianchen3/project/output/E0/magus_working_dir/graph/temp_backbone_8_mafft.txt
2025-04-05 22:21:31    Exit code: 1
2025-04-05 22:21:31    Output: /u/ianchen3/methods/MAGUS/magus/tools/mafft/mafftdir/bin/mafft: line 2719: 1686356 Killed                  "$prefix/tbfast" _ -u $unalignlevel $localparam -C $numthreads $seqtype $model -g $lexp -f $lgop -Q $spfactor -h $laof -L $usenaivepairscore $focusarg _ -+ $iterate -W $minimumweight -V "-"$gopdist -s $unalignlevel $legacygapopt $mergearg $termgapopt $outnum $addarg $add2ndhalfarg -C $numthreadstb $rnaopt $weightopt $treeinopt $treeoutopt $distoutopt $seqtype $model -f "-"$gop -Q $spfactor -h $aof $param_fft $localparam $algopt $treealg $scoreoutarg $focusarg < infile > /dev/null 2>> "$progressfile"

2025-04-05 22:21:31    Task for /u/ianchen3/project/output/E0/magus_working_dir/graph/backbone_8_mafft.txt threw an exception:
Command '/u/ianchen3/methods/MAGUS/magus/tools/mafft/mafft --localpair --maxiterate 1000 --ep 0.123 --quiet --thread 64 --anysymbol /u/ianchen3/project/output/E0/magus_working_dir/graph/backbone_8_unalign.txt > /u/ianchen3/project/output/E0/magus_working_dir/graph/temp_backbone_8_mafft.txt' returned non-zero exit status 1.
2025-04-05 22:21:31    Traceback (most recent call last):
  File "/u/ianchen3/methods/MAGUS/magus/tasks/task.py", line 59, in run
    func(**self.taskArgs)
  File "/u/ianchen3/methods/MAGUS/magus/tools/external_tools.py", line 19, in runCommand
    runner.check_returncode()
  File "/usr/lib64/python3.9/subprocess.py", line 460, in check_returncode
    raise CalledProcessError(self.returncode, self.args, self.stdout,
subprocess.CalledProcessError: Command '/u/ianchen3/methods/MAGUS/magus/tools/mafft/mafft --localpair --maxiterate 1000 --ep 0.123 --quiet --thread 64 --anysymbol /u/ianchen3/project/output/E0/magus_working_dir/graph/backbone_8_unalign.txt > /u/ianchen3/project/output/E0/magus_working_dir/graph/temp_backbone_8_mafft.txt' returned non-zero exit status 1.

2025-04-05 22:21:51    Command encountered error: /u/ianchen3/methods/MAGUS/magus/tools/mafft/mafft --localpair --maxiterate 1000 --ep 0.123 --quiet --thread 64 --anysymbol /u/ianchen3/project/output/E0/magus_working_dir/graph/backbone_6_unalign.txt > /u/ianchen3/project/output/E0/magus_working_dir/graph/temp_backbone_6_mafft.txt
2025-04-05 22:21:51    Exit code: 1
2025-04-05 22:21:51    Output: /u/ianchen3/methods/MAGUS/magus/tools/mafft/mafftdir/bin/mafft: line 2719: 1686084 Killed                  "$prefix/tbfast" _ -u $unalignlevel $localparam -C $numthreads $seqtype $model -g $lexp -f $lgop -Q $spfactor -h $laof -L $usenaivepairscore $focusarg _ -+ $iterate -W $minimumweight -V "-"$gopdist -s $unalignlevel $legacygapopt $mergearg $termgapopt $outnum $addarg $add2ndhalfarg -C $numthreadstb $rnaopt $weightopt $treeinopt $treeoutopt $distoutopt $seqtype $model -f "-"$gop -Q $spfactor -h $aof $param_fft $localparam $algopt $treealg $scoreoutarg $focusarg < infile > /dev/null 2>> "$progressfile"

2025-04-05 22:21:51    Task for /u/ianchen3/project/output/E0/magus_working_dir/graph/backbone_6_mafft.txt threw an exception:
Command '/u/ianchen3/methods/MAGUS/magus/tools/mafft/mafft --localpair --maxiterate 1000 --ep 0.123 --quiet --thread 64 --anysymbol /u/ianchen3/project/output/E0/magus_working_dir/graph/backbone_6_unalign.txt > /u/ianchen3/project/output/E0/magus_working_dir/graph/temp_backbone_6_mafft.txt' returned non-zero exit status 1.
2025-04-05 22:21:51    Traceback (most recent call last):
  File "/u/ianchen3/methods/MAGUS/magus/tasks/task.py", line 59, in run
    func(**self.taskArgs)
  File "/u/ianchen3/methods/MAGUS/magus/tools/external_tools.py", line 19, in runCommand
    runner.check_returncode()
  File "/usr/lib64/python3.9/subprocess.py", line 460, in check_returncode
    raise CalledProcessError(self.returncode, self.args, self.stdout,
subprocess.CalledProcessError: Command '/u/ianchen3/methods/MAGUS/magus/tools/mafft/mafft --localpair --maxiterate 1000 --ep 0.123 --quiet --thread 64 --anysymbol /u/ianchen3/project/output/E0/magus_working_dir/graph/backbone_6_unalign.txt > /u/ianchen3/project/output/E0/magus_working_dir/graph/temp_backbone_6_mafft.txt' returned non-zero exit status 1.

2025-04-05 22:23:18    Command encountered error: /u/ianchen3/methods/MAGUS/magus/tools/mafft/mafft --localpair --maxiterate 1000 --ep 0.123 --quiet --thread 64 --anysymbol /u/ianchen3/project/output/E0/magus_working_dir/graph/backbone_7_unalign.txt > /u/ianchen3/project/output/E0/magus_working_dir/graph/temp_backbone_7_mafft.txt
2025-04-05 22:23:18    Exit code: 1
2025-04-05 22:23:18    Output: /u/ianchen3/methods/MAGUS/magus/tools/mafft/mafftdir/bin/mafft: line 2719: 1689811 Killed                  "$prefix/tbfast" _ -u $unalignlevel $localparam -C $numthreads $seqtype $model -g $lexp -f $lgop -Q $spfactor -h $laof -L $usenaivepairscore $focusarg _ -+ $iterate -W $minimumweight -V "-"$gopdist -s $unalignlevel $legacygapopt $mergearg $termgapopt $outnum $addarg $add2ndhalfarg -C $numthreadstb $rnaopt $weightopt $treeinopt $treeoutopt $distoutopt $seqtype $model -f "-"$gop -Q $spfactor -h $aof $param_fft $localparam $algopt $treealg $scoreoutarg $focusarg < infile > /dev/null 2>> "$progressfile"

2025-04-05 22:23:18    Task for /u/ianchen3/project/output/E0/magus_working_dir/graph/backbone_7_mafft.txt threw an exception:
Command '/u/ianchen3/methods/MAGUS/magus/tools/mafft/mafft --localpair --maxiterate 1000 --ep 0.123 --quiet --thread 64 --anysymbol /u/ianchen3/project/output/E0/magus_working_dir/graph/backbone_7_unalign.txt > /u/ianchen3/project/output/E0/magus_working_dir/graph/temp_backbone_7_mafft.txt' returned non-zero exit status 1.
2025-04-05 22:23:18    Traceback (most recent call last):
  File "/u/ianchen3/methods/MAGUS/magus/tasks/task.py", line 59, in run
    func(**self.taskArgs)
  File "/u/ianchen3/methods/MAGUS/magus/tools/external_tools.py", line 19, in runCommand
    runner.check_returncode()
  File "/usr/lib64/python3.9/subprocess.py", line 460, in check_returncode
    raise CalledProcessError(self.returncode, self.args, self.stdout,
subprocess.CalledProcessError: Command '/u/ianchen3/methods/MAGUS/magus/tools/mafft/mafft --localpair --maxiterate 1000 --ep 0.123 --quiet --thread 64 --anysymbol /u/ianchen3/project/output/E0/magus_working_dir/graph/backbone_7_unalign.txt > /u/ianchen3/project/output/E0/magus_working_dir/graph/temp_backbone_7_mafft.txt' returned non-zero exit status 1.

